Workbook

Sheet Home Worksheet
A1: Home Page for Nessus Report_20251111145451
A2: host_scan_data
A3: ScanInfo
A4: CVSSv3 Score Total
A5: Information
A6: CPE Report Data
A7: Device Type
A8: HostConfigData
A9: portScanData
A10: Unix Policy
A11: UserAccountData
A12: Summary Report Data
... A19: Overall Summary Data
A20: Number of IP's Scanned | B20: 2
A21: Number of Discovered Systems | B21: 1
A23: Total Unique Critical Severity Vulnerability | B23: 0
A24: Total Unique High Severity Vulnerability | B24: 0
A25: Total Unique Medium Severity Vulnerability | B25: 0
A26: Total Unique Low Severity Vulnerability | B26: 0
A27: Total Unique Informational Severity Vulnerability | B27: 8
A29: Total Count of Critical Severity Vulnerability | B29: N/A
A30: Total Count of High Severity Vulnerability | B30: N/A
A31: Total Count of Medium Severity Vulnerability | B31: N/A
A32: Total Count of Low Severity Vulnerability | B32: N/A
A34: The most common Critical Severity vulnerability
A35: The most common high Severity vulnerability
A36: Number of System with a critical(4) Severity Vulnerability | B36: =COUNTIF(HostConfigData!M3:M3,">0") -> 0
A37: Number of System with a High(3) Severity Vulnerability | B37: =COUNTIF(HostConfigData!L3:L3,">0") -> 0
A38: Number of System with a Medium(2) Severity Vulnerability | B38: =COUNTIF(HostConfigData!K3:K3,">0") -> 0
A39: Number of System with a Low(1) Severity Vulnerability | B39: =COUNTIF(HostConfigData!J3:J3,">0") -> 0
A40: Number of System with a Informational(NONE-0) Severity Vulnerability | B40: =COUNTIF(HostConfigData!I3:I3,">0") -> 1

Sheet host_scan_data
A1: 'Home Worksheet'!A1
A2: File | B2: IP Address | C2: FQDN | D2: Plugin ID | E2: Protocol | F2: Port | G2: Severity | H2: Plugin Family | I2: Plugin Name | J2: CVSSv3 Vector | K2: CVSSv3 Base Score | L2: CVSSv3 Temporal Score | M2: Exploitability Ease | N2: Exploit Available | O2: Exploit Framework Canvas | P2: Exploit Framework Metasploit | Q2: Exploit Framework Core | R2: Metasploit Name | S2: Canvas Package | T2: Plugin Output
A3: oracle_post.nessus | B3: 192.168.0.75 | C3: RB-NT-201.redbelt.com.br | D3: 141118 | E3: tcp | F3: 22 | G3: 0 | H3: Settings | I3: Target Credential Status by Authentication Protocol - Valid Credentials Provided | J3: N/A | K3: N/A | L3: N/A | M3: N/A | N3: N/A | O3: N/A | P3: N/A | Q3: N/A | R3: N/A | S3: N/A | T3: |Nessus was able to log in to the remote host via the following :||User: 'master'|Port: 22|Proto: SSH|Method: password|Escalation: su_sudo|
A4: oracle_post.nessus | B4: 192.168.0.75 | C4: RB-NT-201.redbelt.com.br | D4: 102094 | E4: tcp | F4: 0 | G4: 0 | H4: Settings | I4: SSH Commands Require Privilege Escalation | J4: N/A | K4: N/A | L4: N/A | M4: N/A | N4: N/A | O4: N/A | P4: N/A | Q4: N/A | R4: N/A | S4: N/A | T4: |Login account : master|Commands failed due to privilege escalation failure:|- Escalation account : master + master| Escalation method : su + sudo| Plugins :| - Plugin Filename : host_tag_nix.nbin| Plugin ID : 87414| Plugin Name : Host Tagging (Linux)| - Command : "sh -c \"echo 8a6fd7ced0914969b04f0d2a1782b4a8 > /etc/tenable_tag && echo OK\""| Response : "sh: /etc/tenable_tag: Permission denied"| Error : ""| - Plugin Filename : ssh_get_info2.nasl| Plugin ID : 97993| Plugin Name : OS Identification and Installed Software Enumeration over SSH v2 (Using New SSH Library)| - Command : "lsmod | grep -q iptable_filter && iptables -L -n -v -t filter"| Response : "iptables v1.4.21: can't initialize iptables table `filter': Permission denied (you must be root)\nPerhaps iptables or your kernel needs to be upgraded."| Error : ""| - Command : "lsmod | grep -q _conntrack_ipv4 && iptables -L -n -v -t nat"| Response : "iptables v1.4.21: can't initialize iptables table `nat': Permission denied (you must be root)\nPerhaps iptables or your kernel needs to be upgraded."| Error : ""| - Command : "lsmod | grep -q iptable_mangle && iptables -L -n -v -t mangle"| Response : "iptables v1.4.21: can't initialize iptables table `mangle': Permission denied (you must be root)\nPerhaps iptables or your kernel needs to be upgraded."| Error : ""| - Plugin Filename : unix_compliance_check.nbin| Plugin ID : 21157| Plugin Name : Unix Compliance Checks| - Command : "LANG=C; echo \"Iy9iaW4vYmFzaAogIHsKICAgbF9ncnViX3Bhc3N3b3JkX2ZpbGU9IiQoZmluZCAvYm9vdCAtdHlwZSBmIC1uYW1lICd1c2VyLmNmZycgISAtZW1wdHkpIgogICBpZiBbIC1mICIkbF9ncnViX3Bhc3N3b3JkX2ZpbGUiIF07IHRoZW4KICAgICAgYXdrIC1GLiAnL15ccypHUlVCMl9QQVNTV09SRD1cUysvIHtwcmludCAkMSIuIiQyIi4iJDN9JyAiJGxfZ3J1Yl9wYXNzd29yZF9maWxlIgogICBmaQogICB9\" | openssl base64 -d -A | bash|cat"| Response : "find: '/boot/efi/EFI/redhat': Permission denied\nfind: '/boot/grub2': Permission denied"| Error : ""| - Command : "LANG=C; echo \"IyEvYmluL2Jhc2gKCnsKICAgbF9vdXRwdXQ9IiIgbF9vdXRwdXQyPSIiCiAgIGZpbGVfbXVnX2NoaygpCiAgIHsKICAgICAgbF9vdXQ9IiIgbF9vdXQyPSIiCiAgICAgIFtbICIkKGRpcm5hbWUgIiRsX2ZpbGUiKSIgPX4gXlwvYm9vdFwvZWZpXC9FRkkgXV0gJiYgbF9wbWFzaz0iMDA3NyIgfHwgbF9wbWFzaz0iMDE3NyIKICAgICAgbF9tYXhwZXJtPSIkKCBwcmludGYgJyVvJyAkKCggMDc3NyAmIH4kbF9wbWFzayApKSApIgogICAgICBpZiBbICQoKCAkbF9tb2RlICYgJGxfcG1hc2sgKSkgLWd0IDAgXTsgdGhlbgogICAgICAgICBsX291dDI9IiRsX291dDJcbiAgIC0gSXMgbW9kZSBcIiRsX21vZGVcIiBhbmQgc2hvdWxkIGJlIG1vZGU6IFwiJGxfbWF4cGVybVwiIG9yIG1vcmUgcmVzdHJpY3RpdmUiCiAgICAgIGVsc2UKICAgICAgICAgbF9vdXQ9IiRsX291dFxuICAgLSBJcyBjb3JyZWN0bHkgbW9kZTogXCIkbF9tb2RlXCIgd2hpY2ggaXMgbW9kZTogXCIkbF9tYXhwZXJtXCIgb3IgbW9yZSByZXN0cmljdGl2ZSIKICAgICAgZmkKICAgICAgaWYgWyAiJGxfdXNlciIgPSAicm9vdCIgXTsgdGhlbgogICAgICAgICBsX291dD0iJGxfb3V0XG4gICAtIElzIGNvcnJlY3RseSBvd25lZCBieSB1c2VyOiBcIiRsX3VzZXJcIiIKICAgICAgZWxzZQogICAgICAgICBsX291dDI9IiRsX291dDJcbiAgIC0gSXMgb3duZWQgYnkgdXNlcjogXCIkbF91c2VyXCIgYW5kIHNob3VsZCBiZSBvd25lZCBieSB1c2VyOiBcInJvb3RcIiIKICAgICAgZmkKICAgICAgaWYgWyAiJGxfZ3JvdXAiID0gInJvb3QiIF07IHRoZW4KICAgICAgICAgbF9vdXQ9IiRsX291dFxuICAgLSBJcyBjb3JyZWN0bHkgZ3JvdXAtb3duZWQgYnkgZ3JvdXA6IFwiJGxfdXNlclwiIgogICAgICBlbHNlCiAgICAgICAgIGxfb3V0Mj0iJGxfb3V0MlxuICAgLSBJcyBncm91cC1vd25lZCBieSBncm91cDogXCIkbF91c2VyXCIgYW5kIHNob3VsZCBiZSBncm91cC1vd25lZCBieSBncm91cDogXCJyb290XCIiCiAgICAgIGZpCiAgICAgIFsgLW4gIiRsX291dCIgXSAmJiBsX291dHB1dD0iJGxfb3V0cHV0XG4gIC0gRmlsZTogXCIkbF9maWxlXCIkbF9vdXRcbiIKICAgICAgWyAtbiAiJGxfb3V0MiIgXSAmJiBsX291dHB1dDI9IiRsX291dHB1dDJcbiAgLSBGaWxlOiBcIiRsX2ZpbGVcIiRsX291dDJcbiIKICAgfQogICB3aGlsZSBJRlM9IHJlYWQgLXIgLWQgJCdcMCcgbF9nZmlsZTsgZG8KICAgICAgd2hpbGUgcmVhZCAtciBsX2ZpbGUgbF9tb2RlIGxfdXNlciBsX2dyb3VwOyBkbwogICAgICAgICBmaWxlX211Z19jaGsKICAgICAgZG9uZSA8PDwgIiQoc3RhdCAtTGMgJyVuICUjYSAlVSAlRycgIiRsX2dmaWxlIikiCiAgIGRvbmUgPCA8KGZpbmQgL2Jvb3QgLXR5cGUgZiBcKCAtbmFtZSAnZ3J1YionIC1vIC1uYW1lICd1c2VyLmNmZycgXCkgLXByaW50MCkKICAgaWYgWyAteiAiJGxfb3V0cHV0MiIgXTsgdGhlbgogICAgICBlY2hvIC1lICJcbi0gQXVkaXQgUmVzdWx0OlxuICAqKiogUEFTUyAqKipcbi0gKiBDb3JyZWN0bHkgc2V0ICogOlxuJGxfb3V0cHV0XG4iCiAgIGVsc2UKICAgICAgZWNobyAtZSAiXG4tIEF1ZGl0IFJlc3VsdDpcbiAgKiogRkFJTCAqKlxuIC0gKiBSZWFzb25zIGZvciBhdWRpdCBmYWlsdXJlICogOlxuJGxfb3V0cHV0MlxuIgogICAgICBbIC1uICIkbF9vdXRwdXQiIF0gJiYgZWNobyAtZSAiIC0gKiBDb3JyZWN0bHkgc2V0ICogOlxuJGxfb3V0cHV0XG4iCiAgIGZpCn0=\" | openssl base64 -d -A | /bin/bash|cat"| Response : "find: '/boot/efi/EFI/redhat': Permission denied\nfind: '/boot/grub2': Permission denied\n\n- Audit Result:\n *** PASS ***\n- * Correctly set * :"| Error : ""| - Command : "LANG=C; echo \"IyEvYmluL2Jhc2gKICB7CiAgcG9ydHM9JCgvYmluL2dyZXAgLXMgLVAgIl4oUG9ydHxNYXRjaCkiIC9ldGMvc3NoL3NzaGRfY29uZmlnIC9ldGMvc3NoL3NzaGRfY29uZmlnLmQvKi5jb25mIHwgL2Jpbi9ncmVwIC1QIC1vICIoUG9ydHxMb2NhbFBvcnQpW1xzXStbXGRdKyIgfCAvYmluL2F3ayAne3ByaW50ICQyfTsgRU5EIHtpZiAoTlIgPT0gMCkgcHJpbnQgIjIyIn0nIHwgL2Jpbi91bmlxKTsgZm9yIHBvcnQgaW4gJHtwb3J0c1tAXX07IGRvIC9zYmluL3NzaGQgLVQgLUMgdXNlcj1yb290IC1DIGhvc3Q9IiQoaG9zdG5hbWUpIiAtQyBhZGRyPSIkKC9iaW4vZ3JlcCAkKGhvc3RuYW1lKSAvZXRjL2hvc3RzIHwgL2Jpbi9hd2sgJ3twcmludCAkMX0nKSIgLUMgbHBvcnQ9JHBvcnQgfCBlY2hvICJwb3J0ICRwb3J0OiAkKC9iaW4vZ3JlcCAtaSBeaG9zdGJhc2VkYXV0aGVudGljYXRpb24pIjsgZG9uZSB8IC9iaW4vYXdrICdCRUdJTiB7Zj0wfSAvSG9zdGJhc2VkQXV0aGVudGljYXRpb24vaSB7IGlmICgkTkYgPT0gInllcyIpIGYrKzsgcHJpbnQgJDB9IEVORCB7aWYgKE5SID09IDApIHByaW50ICJGYWlsOiBubyByZXN1bHRzIHJldHVybmVkIjsgZWxzZSBpZiAoZiA+IDApIHByaW50ICJGYWlsIjsgZWxzZSBwcmludCAiUGFzcyIgfScKICB9\" | openssl base64 -d -A | /bin/bash|cat"| Response : "/etc/ssh/sshd_config: Permission denied\nport 22: \nPass"| Error : ""| - Command : "LANG=C; cat '/etc/ssh/sshd_config'|cat"| Response : "cat: /etc/ssh/sshd_config: Permission denied"| Error : ""| - Command : "LANG=C; echo \"IyEvYmluL2Jhc2gKICB7CiAgcG9ydHM9JCgvYmluL2dyZXAgLXMgLVAgIl4oUG9ydHxNYXRjaCkiIC9ldGMvc3NoL3NzaGRfY29uZmlnIC9ldGMvc3NoL3NzaGRfY29uZmlnLmQvKi5jb25mIHwgL2Jpbi9ncmVwIC1QIC1vICIoUG9ydHxMb2NhbFBvcnQpW1xzXStbXGRdKyIgfCAvYmluL2F3ayAne3ByaW50ICQyfTsgRU5EIHtpZiAoTlIgPT0gMCkgcHJpbnQgIjIyIn0nIHwgL2Jpbi91bmlxKTsgZm9yIHBvcnQgaW4gJHtwb3J0c1tAXX07IGRvIC9zYmluL3NzaGQgLVQgLUMgdXNlcj1yb290IC1DIGhvc3Q9IiQoaG9zdG5hbWUpIiAtQyBhZGRyPSIkKC9iaW4vZ3JlcCAkKGhvc3RuYW1lKSAvZXRjL2hvc3RzIHwgL2Jpbi9hd2sgJ3twcmludCAkMX0nKSIgLUMgbHBvcnQ9JHBvcnQgfCBlY2hvICJwb3J0ICRwb3J0OiAkKC9iaW4vZ3JlcCAtaSBeaWdub3Jlcmhvc3RzKSI7IGRvbmUgfCAvYmluL2F3ayAnQkVHSU4ge2Y9MH0gL0lnbm9yZVJob3N0cy9pIHsgaWYgKCRORiA9PSAibm8iKSBmKys7IHByaW50ICQwfSBFTkQge2lmIChOUiA9PSAwKSBwcmludCAiRmFpbDogbm8gcmVzdWx0cyByZXR1cm5lZCI7IGVsc2UgaWYgKGYgPiAwKSBwcmludCAiRmFpbCI7IGVsc2UgcHJpbnQgIlBhc3MiIH0nCiAgfQ==\" | openssl base64 -d -A | /bin/bash|cat"| Response : "/etc/ssh/sshd_config: Permission denied\nport 22: \nPass"| Error : ""| - Command : "LANG=C; echo \"IyEvYmluL2Jhc2gKICB7CiAgcG9ydHM9JCgvYmluL2dyZXAgLXMgLVAgIl4oUG9ydHxNYXRjaCkiIC9ldGMvc3NoL3NzaGRfY29uZmlnIC9ldGMvc3NoL3NzaGRfY29uZmlnLmQvKi5jb25mIHwgL2Jpbi9ncmVwIC1QIC1vICIoUG9ydHxMb2NhbFBvcnQpW1xzXStbXGRdKyIgfCAvYmluL2F3ayAne3ByaW50ICQyfTsgRU5EIHtpZiAoTlIgPT0gMCkgcHJpbnQgIjIyIn0nIHwgL2Jpbi91bmlxKTsgZm9yIHBvcnQgaW4gJHtwb3J0c1tAXX07IGRvIC9zYmluL3NzaGQgLVQgLUMgdXNlcj1yb290IC1DIGhvc3Q9IiQoaG9zdG5hbWUpIiAtQyBhZGRyPSIkKC9iaW4vZ3JlcCAkKGhvc3RuYW1lKSAvZXRjL2hvc3RzIHwgL2Jpbi9hd2sgJ3twcmludCAkMX0nKSIgLUMgbHBvcnQ9JHBvcnQgfCBlY2hvICJwb3J0ICRwb3J0OiAkKC9iaW4vZ3JlcCAtaSBea2V4YWxnb3JpdGhtcykiOyBkb25lIHwgL2Jpbi9hd2sgJ0JFR0lOIHtmPTB9IC9rZXhhbGdvcml0aG1zL2kgeyBpZiAoJE5GIH4gIihkaWZmaWUtaGVsbG1hbi1ncm91cDEtc2hhMXxkaWZmaWUtaGVsbG1hbi1ncm91cDE0LXNoYTF8ZGlmZmllLWhlbGxtYW4tZ3JvdXAtZXhjaGFuZ2Utc2hhMSkiKSBmKys7IHByaW50ICQwfSBFTkQge2lmIChOUiA9PSAwKSBwcmludCAiRmFpbDogbm8gcmVzdWx0cyByZXR1cm5lZCI7IGVsc2UgaWYgKGYgPiAwKSBwcmludCAiRmFpbCI7IGVsc2UgcHJpbnQgIlBhc3MiIH0nCiAgfQ==\" | openssl base64 -d -A | /bin/bash|cat"| Response : "/etc/ssh/sshd_config: Permission denied\nport 22: \nPass"| Error : ""| - Command : "LANG=C; echo \"IyEvYmluL2Jhc2gKICB7CiAgcG9ydHM9JCgvYmluL2dyZXAgLXMgLVAgIl4oUG9ydHxNYXRjaCkiIC9ldGMvc3NoL3NzaGRfY29uZmlnIC9ldGMvc3NoL3NzaGRfY29uZmlnLmQvKi5jb25mIHwgL2Jpbi9ncmVwIC1QIC1vICIoUG9ydHxMb2NhbFBvcnQpW1xzXStbXGRdKyIgfCAvYmluL2F3ayAne3ByaW50ICQyfTsgRU5EIHtpZiAoTlIgPT0gMCkgcHJpbnQgIjIyIn0nIHwgL2Jpbi91bmlxKTsgZm9yIHBvcnQgaW4gJHtwb3J0c1tAXX07IGRvIC9zYmluL3NzaGQgLVQgLUMgdXNlcj1yb290IC1DIGhvc3Q9IiQoaG9zdG5hbWUpIiAtQyBhZGRyPSIkKC9iaW4vZ3JlcCAkKGhvc3RuYW1lKSAvZXRjL2hvc3RzIHwgL2Jpbi9hd2sgJ3twcmludCAkMX0nKSIgLUMgbHBvcnQ9JHBvcnQgfCBlY2hvICJwb3J0ICRwb3J0OiAkKC9iaW4vZ3JlcCAtaSBebG9naW5ncmFjZXRpbWUpIjsgZG9uZSB8IC9iaW4vYXdrICdCRUdJTiB7Zj0wfSAvbG9naW5ncmFjZXRpbWUvaSB7IGlmICgkTkYgIX4gL14oWzEtOV18WzEtNV1bMC05XXw2MHwxbSkkLykgZisrOyBwcmludCAkMH0gRU5EIHtpZiAoTlIgPT0gMCkgcHJpbnQgIkZhaWw6IG5vIHJlc3VsdHMgcmV0dXJuZWQiOyBlbHNlIGlmIChmID4gMCkgcHJpbnQgIkZhaWwiOyBlbHNlIHByaW50ICJQYXNzIiB9JwogIH0=\" | openssl base64 -d -A | /bin/bash|cat"| Response : "/etc/ssh/sshd_config: Permission denied\nport 22: \nFail"| Error : ""| - Command : "LANG=C; echo \"IyEvYmluL2Jhc2gKICB7CiAgcG9ydHM9JCgvYmluL2dyZXAgLXMgLVAgIl4oUG9ydHxNYXRjaCkiIC9ldGMvc3NoL3NzaGRfY29uZmlnIC9ldGMvc3NoL3NzaGRfY29uZmlnLmQvKi5jb25mIHwgL2Jpbi9ncmVwIC1QIC1vICIoUG9ydHxMb2NhbFBvcnQpW1xzXStbXGRdKyIgfCAvYmluL2F3ayAne3ByaW50ICQyfTsgRU5EIHtpZiAoTlIgPT0gMCkgcHJpbnQgIjIyIn0nIHwgL2Jpbi91bmlxKTsgZm9yIHBvcnQgaW4gJHtwb3J0c1tAXX07IGRvIC9zYmluL3NzaGQgLVQgLUMgdXNlcj1yb290IC1DIGhvc3Q9IiQoaG9zdG5hbWUpIiAtQyBhZGRyPSIkKC9iaW4vZ3JlcCAkKGhvc3RuYW1lKSAvZXRjL2hvc3RzIHwgL2Jpbi9hd2sgJ3twcmludCAkMX0nKSIgLUMgbHBvcnQ9JHBvcnQgfCBlY2hvICJwb3J0ICRwb3J0OiAkKC9iaW4vZ3JlcCAtaSBsb2dsZXZlbCkiOyBkb25lIHwgL2Jpbi9hd2sgJ0JFR0lOIHtmPTB9IC9Mb2dMZXZlbC9pIHsgaWYgKCRORiAhfiAvXihJTkZPfFZFUkJPU0UpJC8pIGYrKzsgcHJpbnQgJDB9IEVORCB7aWYgKE5SID09IDApIHByaW50ICJGYWlsOiBubyByZXN1bHRzIHJldHVybmVkIjsgZWxzZSBpZiAoZiA+IDApIHByaW50ICJGYWlsIjsgZWxzZSBwcmludCAiUGFzcyIgfScKICB9\" | openssl base64 -d -A | /bin/bash|cat"| Response : "/etc/ssh/sshd_config: Permission denied\nport 22: \nFail"| Error : ""| - Command : "LANG=C; echo \"IyEvYmluL2Jhc2gKewpwb3J0cz0kKC9iaW4vZ3JlcCAtcyAtUCAiXihQb3J0fE1hdGNoKSIgL2V0Yy9zc2gvc3NoZF9jb25maWcgL2V0Yy9zc2hkX2NvbmZpZy5kLyouY29uZiB8IC9iaW4vZ3JlcCAtUCAtbyAiKFBvcnR8TG9jYWxQb3J0KVtcc10rW1xkXSsiIHwgL2Jpbi9hd2sgJ3twcmludCAkMn07IEVORCB7aWYgKE5SID09IDApIHByaW50ICIyMiJ9JyB8IC9iaW4vdW5pcSk7IGZvciBwb3J0IGluICR7cG9ydHNbQF19OyBkbyAvc2Jpbi9zc2hkIC1UIC1DIHVzZXI9cm9vdCAtQyBob3N0PSIkKGhvc3RuYW1lKSIgLUMgYWRkcj0iJCgvYmluL2dyZXAgJChob3N0bmFtZSkgL2V0Yy9ob3N0cyB8IC9iaW4vYXdrICd7cHJpbnQgJDF9JykiIC1DIGxwb3J0PSRwb3J0IHwgZWNobyAicG9ydCAkcG9ydDogJCgvYmluL2dyZXAgLUVpICdebWFjc1xzJykiOyBkb25lIHwgL2Jpbi9hd2sgJ0JFR0lOIHtmPTB9IC9cc21hY3Nccy9pIHsgaWYgKCRORiB+ICIoaG1hYy1tZDV8aG1hYy1tZDUtOTZ8aG1hYy1yaXBlbWQxNjB8aG1hYy1zaGExLTk2fHVtYWMtNjRAb3BlbnNzaC5jb218aG1hYy1tZDUtZXRtQG9wZW5zc2guY29tfGhtYWMtbWQ1LTk2LWV0bUBvcGVuc3NoLmNvbXxobWFjLXJpcGVtZDE2MC1ldG1Ab3BlbnNzaC5jb218aG1hYy1zaGExLTk2LWV0bUBvcGVuc3NoLmNvbXx1bWFjLTY0LWV0bUBvcGVuc3NoLmNvbSkiKSBmKys7IHByaW50ICQwfSBFTkQge2lmIChOUiA9PSAwKSBwcmludCAiRmFpbDogbm8gcmVzdWx0cyByZXR1cm5lZCI7IGVsc2UgaWYgKGYgPiAwKSBwcmludCAiRmFpbCI7IGVsc2UgcHJpbnQgIlBhc3MiIH0nCn0=\" | openssl base64 -d -A | /bin/bash|cat"| Response : "/etc/ssh/sshd_config: Permission denied\nport 22: \nPass"| Error : ""| - Command : "LANG=C; echo \"IyEvYmluL2Jhc2gKICB7CiAgcG9ydHM9JCgvYmluL2dyZXAgLXMgLVAgIl4oUG9ydHxNYXRjaCkiIC9ldGMvc3NoL3NzaGRfY29uZmlnIC9ldGMvc3NoL3NzaGRfY29uZmlnLmQvKi5jb25mIHwgL2Jpbi9ncmVwIC1QIC1vICIoUG9ydHxMb2NhbFBvcnQpW1xzXStbXGRdKyIgfCAvYmluL2F3ayAne3ByaW50ICQyfTsgRU5EIHtpZiAoTlIgPT0gMCkgcHJpbnQgIjIyIn0nIHwgL2Jpbi91bmlxKTsgZm9yIHBvcnQgaW4gJHtwb3J0c1tAXX07IGRvIC9zYmluL3NzaGQgLVQgLUMgdXNlcj1yb290IC1DIGhvc3Q9IiQoaG9zdG5hbWUpIiAtQyBhZGRyPSIkKC9iaW4vZ3JlcCAkKGhvc3RuYW1lKSAvZXRjL2hvc3RzIHwgL2Jpbi9hd2sgJ3twcmludCAkMX0nKSIgLUMgbHBvcnQ9JHBvcnQgfCBlY2hvICJwb3J0ICRwb3J0OiAkKC9iaW4vZ3JlcCAtaSBebWF4YXV0aHRyaWVzKSI7IGRvbmUgfCAvYmluL2F3ayAnQkVHSU4ge2Y9MH0gL21heGF1dGh0cmllcy9pIHsgaWYgKCRORiAhfiAvXlswLTRdJC8pIGYrKzsgcHJpbnQgJDB9IEVORCB7aWYgKE5SID09IDApIHByaW50ICJGYWlsOiBubyByZXN1bHRzIHJldHVybmVkIjsgZWxzZSBpZiAoZiA+IDApIHByaW50ICJGYWlsIjsgZWxzZSBwcmludCAiUGFzcyIgfScKICB9\" | openssl base64 -d -A | /bin/bash|cat"| Response : "/etc/ssh/sshd_config: Permission denied\nport 22: \nFail"| Error : ""| - Command : "LANG=C; echo \"IyEvYmluL2Jhc2gKICB7CiAgcG9ydHM9JCgvYmluL2dyZXAgLXMgLVAgIl4oUG9ydHxNYXRjaCkiIC9ldGMvc3NoL3NzaGRfY29uZmlnIC9ldGMvc3NoL3NzaGRfY29uZmlnLmQvKi5jb25mIHwgL2Jpbi9ncmVwIC1QIC1vICIoUG9ydHxMb2NhbFBvcnQpW1xzXStbXGRdKyIgfCAvYmluL2F3ayAne3ByaW50ICQyfTsgRU5EIHtpZiAoTlIgPT0gMCkgcHJpbnQgIjIyIn0nIHwgL2Jpbi91bmlxKTsgZm9yIHBvcnQgaW4gJHtwb3J0c1tAXX07IGRvIC9zYmluL3NzaGQgLVQgLUMgdXNlcj1yb290IC1DIGhvc3Q9IiQoaG9zdG5hbWUpIiAtQyBhZGRyPSIkKC9iaW4vZ3JlcCAkKGhvc3RuYW1lKSAvZXRjL2hvc3RzIHwgL2Jpbi9hd2sgJ3twcmludCAkMX0nKSIgLUMgbHBvcnQ9JHBvcnQgfCBlY2hvICJwb3J0ICRwb3J0OiAkKC9iaW4vZ3JlcCAtaSBebWF4c2Vzc2lvbnMpIjsgZG9uZSB8IC9iaW4vYXdrICdCRUdJTiB7Zj0wfSAvbWF4c2Vzc2lvbnMvaSB7IGlmICgkTkYgIX4gL14oWzAtOV18MTApJC8pIGYrKzsgcHJpbnQgJDB9IEVORCB7aWYgKE5SID09IDApIHByaW50ICJGYWlsOiBubyByZXN1bHRzIHJldHVybmVkIjsgZWxzZSBpZiAoZiA+IDApIHByaW50ICJGYWlsIjsgZWxzZSBwcmludCAiUGFzcyIgfScKICB9\" | openssl base64 -d -A | /bin/bash|cat"| Response : "/etc/ssh/sshd_config: Permission denied\nport 22: \nFail"| Error : ""| - Command : "LANG=C; echo \"IyEvYmluL2Jhc2gKICB7CiAgcG9ydHM9JCgvYmluL2dyZXAgLXMgLVAgIl4oUG9ydHxNYXRjaCkiIC9ldGMvc3NoL3NzaGRfY29uZmlnIC9ldGMvc3NoL3NzaGRfY29uZmlnLmQvKi5jb25mIHwgL2Jpbi9ncmVwIC1QIC1vICIoUG9ydHxMb2NhbFBvcnQpW1xzXStbXGRdKyIgfCAvYmluL2F3ayAne3ByaW50ICQyfTsgRU5EIHtpZiAoTlIgPT0gMCkgcHJpbnQgIjIyIn0nIHwgL2Jpbi91bmlxKTsgZm9yIHBvcnQgaW4gJHtwb3J0c1tAXX07IGRvIC9zYmluL3NzaGQgLVQgLUMgdXNlcj1yb290IC1DIGhvc3Q9IiQoaG9zdG5hbWUpIiAtQyBhZGRyPSIkKC9iaW4vZ3JlcCAkKGhvc3RuYW1lKSAvZXRjL2hvc3RzIHwgL2Jpbi9hd2sgJ3twcmludCAkMX0nKSIgLUMgbHBvcnQ9JHBvcnQgfCBlY2hvICJwb3J0ICRwb3J0OiAkKC9iaW4vZ3JlcCAtaSBebWF4c3RhcnR1cHMpIjsgZG9uZSB8IC9iaW4vYXdrICdCRUdJTiB7Zj0wfSAvbWF4c3RhcnR1cHMvaSB7IGlmICgkTkYgIX4gL14oWzEtOV18MTApOihbMS05XXxbMTJdWzAtOV18MzApOihbMS05XXxbMS01XVswLTldfDYwKSQvKSBmKys7IHByaW50ICQwfSBFTkQge2lmIChOUiA9PSAwKSBwcmludCAiRmFpbDogbm8gcmVzdWx0cyByZXR1cm5lZCI7IGVsc2UgaWYgKGYgPiAwKSBwcmludCAiRmFpbCI7IGVsc2UgcHJpbnQgIlBhc3MiIH0nCiAgfQ==\" | openssl base64 -d -A | /bin/bash|cat"| Response : "/etc/ssh/sshd_config: Permission denied\nport 22: \nFail"| Error : ""| - Command : "LANG=C; echo \"IyEvYmluL2Jhc2gKICB7CiAgcG9ydHM9JCgvYmluL2dyZXAgLXMgLVAgIl4oUG9ydHxNYXRjaCkiIC9ldGMvc3NoL3NzaGRfY29uZmlnIC9ldGMvc3NoL3NzaGRfY29uZmlnLmQvKi5jb25mIHwgL2Jpbi9ncmVwIC1QIC1vICIoUG9ydHxMb2NhbFBvcnQpW1xzXStbXGRdKyIgfCAvYmluL2F3ayAne3ByaW50ICQyfTsgRU5EIHtpZiAoTlIgPT0gMCkgcHJpbnQgIjIyIn0nIHwgL2Jpbi91bmlxKTsgZm9yIHBvcnQgaW4gJHtwb3J0c1tAXX07IGRvIC9zYmluL3NzaGQgLVQgLUMgdXNlcj1yb290IC1DIGhvc3Q9IiQoaG9zdG5hbWUpIiAtQyBhZGRyPSIkKC9iaW4vZ3JlcCAkKGhvc3RuYW1lKSAvZXRjL2hvc3RzIHwgL2Jpbi9hd2sgJ3twcmludCAkMX0nKSIgLUMgbHBvcnQ9JHBvcnQgfCBlY2hvICJwb3J0ICRwb3J0OiAkKC9iaW4vZ3JlcCAtaSBeUGVybWl0RW1wdHlQYXNzd29yZHMpIjsgZG9uZSB8IC9iaW4vYXdrICdCRUdJTiB7Zj0wfSAvUGVybWl0RW1wdHlQYXNzd29yZHMvaSB7IGlmICgkTkYgPT0gInllcyIpIGYrKzsgcHJpbnQgJDB9IEVORCB7aWYgKE5SID09IDApIHByaW50ICJGYWlsOiBubyByZXN1bHRzIHJldHVybmVkIjsgZWxzZSBpZiAoZiA+IDApIHByaW50ICJGYWlsIjsgZWxzZSBwcmludCAiUGFzcyIgfScKICB9\" | openssl base64 -d -A | /bin/bash|cat"| Response : "/etc/ssh/sshd_config: Permission denied\nport 22: \nPass"| Error : ""| - Command : "LANG=C; echo \"IyEvYmluL2Jhc2gKICB7CiAgcG9ydHM9JCgvYmluL2dyZXAgLXMgLVAgIl4oUG9ydHxNYXRjaCkiIC9ldGMvc3NoL3NzaGRfY29uZmlnIC9ldGMvc3NoL3NzaGRfY29uZmlnLmQvKi5jb25mIHwgL2Jpbi9ncmVwIC1QIC1vICIoUG9ydHxMb2NhbFBvcnQpW1xzXStbXGRdKyIgfCAvYmluL2F3ayAne3ByaW50ICQyfTsgRU5EIHtpZiAoTlIgPT0gMCkgcHJpbnQgIjIyIn0nIHwgL2Jpbi91bmlxKTsgZm9yIHBvcnQgaW4gJHtwb3J0c1tAXX07IGRvIC9zYmluL3NzaGQgLVQgLUMgdXNlcj1yb290IC1DIGhvc3Q9IiQoaG9zdG5hbWUpIiAtQyBhZGRyPSIkKC9iaW4vZ3JlcCAkKGhvc3RuYW1lKSAvZXRjL2hvc3RzIHwgL2Jpbi9hd2sgJ3twcmludCAkMX0nKSIgLUMgbHBvcnQ9JHBvcnQgfCBlY2hvICJwb3J0ICRwb3J0OiAkKC9iaW4vZ3JlcCAtaSBecGVybWl0cm9vdGxvZ2luKSI7IGRvbmUgfCAvYmluL2F3ayAnQkVHSU4ge2Y9MH0gL3Blcm1pdHJvb3Rsb2dpbi9pIHsgaWYgKCRORiA9PSAieWVzIikgZisrOyBwcmludCAkMH0gRU5EIHtpZiAoTlIgPT0gMCkgcHJpbnQgIkZhaWw6IG5vIHJlc3VsdHMgcmV0dXJuZWQiOyBlbHNlIGlmIChmID4gMCkgcHJpbnQgIkZhaWwiOyBlbHNlIHByaW50ICJQYXNzIn0nCiAgfQ==\" | openssl base64 -d -A | /bin/bash|cat"| Response : "/etc/ssh/sshd_config: Permission denied\nport 22: \nPass"| Error : ""| - Command : "LANG=C; echo \"IyEvYmluL2Jhc2gKICB7CiAgcG9ydHM9JCgvYmluL2dyZXAgLXMgLVAgIl4oUG9ydHxNYXRjaCkiIC9ldGMvc3NoL3NzaGRfY29uZmlnIC9ldGMvc3NoL3NzaGRfY29uZmlnLmQvKi5jb25mIHwgL2Jpbi9ncmVwIC1QIC1vICIoUG9ydHxMb2NhbFBvcnQpW1xzXStbXGRdKyIgfCAvYmluL2F3ayAne3ByaW50ICQyfTsgRU5EIHtpZiAoTlIgPT0gMCkgcHJpbnQgIjIyIn0nIHwgL2Jpbi91bmlxKTsgZm9yIHBvcnQgaW4gJHtwb3J0c1tAXX07IGRvIC9zYmluL3NzaGQgLVQgLUMgdXNlcj1yb290IC1DIGhvc3Q9IiQoaG9zdG5hbWUpIiAtQyBhZGRyPSIkKC9iaW4vZ3JlcCAkKGhvc3RuYW1lKSAvZXRjL2hvc3RzIHwgL2Jpbi9hd2sgJ3twcmludCAkMX0nKSIgLUMgbHBvcnQ9JHBvcnQgfCBlY2hvICJwb3J0ICRwb3J0OiAkKC9iaW4vZ3JlcCAtaSBeUGVybWl0RW1wdHlQYXNzd29yZHMpIjsgZG9uZSB8IC9iaW4vYXdrICdCRUdJTiB7Zj0wfSAvUGVybWl0RW1wdHlQYXNzd29yZHMvaSB7IGlmICgkTkYgPT0gInllcyIpIGYrKzsgcHJpbnQgJDB9IEVORCB7aWYgKE5SID09IDApIHByaW50ICJGYWlsOiBubyByZXN1bHRzIHJldHVybmVkIjsgZWxzZSBpZiAoZiA+IDApIHByaW50ICJGYWlsIjsgZWxzZSBwcmludCAiUGFzcyIgfScKICB9\" | openssl base64 -d -A | /bin/bash|cat"| Response : "/etc/ssh/sshd_config: Permission denied\nport 22: \nPass"| Error : ""| - Command : "LANG=C; echo \"IyEvYmluL2Jhc2gKICB7CiAgcG9ydHM9JCgvYmluL2dyZXAgLXMgLVAgIl4oUG9ydHxNYXRjaCkiIC9ldGMvc3NoL3NzaGRfY29uZmlnIC9ldGMvc3NoL3NzaGRfY29uZmlnLmQvKi5jb25mIHwgL2Jpbi9ncmVwIC1QIC1vICIoUG9ydHxMb2NhbFBvcnQpW1xzXStbXGRdKyIgfCAvYmluL2F3ayAne3ByaW50ICQyfTsgRU5EIHtpZiAoTlIgPT0gMCkgcHJpbnQgIjIyIn0nIHwgL2Jpbi91bmlxKTsgZm9yIHBvcnQgaW4gJHtwb3J0c1tAXX07IGRvIC9zYmluL3NzaGQgLVQgLUMgdXNlcj1yb290IC1DIGhvc3Q9IiQoaG9zdG5hbWUpIiAtQyBhZGRyPSIkKC9iaW4vZ3JlcCAkKGhvc3RuYW1lKSAvZXRjL2hvc3RzIHwgL2Jpbi9hd2sgJ3twcmludCAkMX0nKSIgLUMgbHBvcnQ9JHBvcnQgfCBlY2hvICJwb3J0ICRwb3J0OiAkKC9iaW4vZ3JlcCAtaSBedXNlcGFtKSI7IGRvbmUgfCAvYmluL2F3ayAnQkVHSU4ge2Y9MH0gL3VzZXBhbS9pIHsgaWYgKCRORiA9PSAibm8iKSBmKys7IHByaW50ICQwfSBFTkQge2lmIChOUiA9PSAwKSBwcmludCAiRmFpbDogbm8gcmVzdWx0cyByZXR1cm5lZCI7IGVsc2UgaWYgKGYgPiAwKSBwcmludCAiRmFpbCI7IGVsc2UgcHJpbnQgIlBhc3MiIH0nCiAgfQ==\" | openssl base64 -d -A | /bin/bash|cat"| Response : "/etc/ssh/sshd_config: Permission denied\nport 22: \nPass"| Error : ""| - Command : "LANG=C; echo \"IyEvYmluL2Jhc2gKICB7CiAgcG9ydHM9JCgvYmluL2dyZXAgLXMgLVAgIl4oUG9ydHxNYXRjaCkiIC9ldGMvc3NoL3NzaGRfY29uZmlnIC9ldGMvc3NoL3NzaGRfY29uZmlnLmQvKi5jb25mIHwgL2Jpbi9ncmVwIC1QIC1vICIoUG9ydHxMb2NhbFBvcnQpW1xzXStbXGRdKyIgfCAvYmluL2F3ayAne3ByaW50ICQyfTsgRU5EIHtpZiAoTlIgPT0gMCkgcHJpbnQgIjIyIn0nIHwgL2Jpbi91bmlxKTsgZm9yIHBvcnQgaW4gJHtwb3J0c1tAXX07IGRvIC9zYmluL3NzaGQgLVQgLUMgdXNlcj1yb290IC1DIGhvc3Q9IiQoaG9zdG5hbWUpIiAtQyBhZGRyPSIkKC9iaW4vZ3JlcCAkKGhvc3RuYW1lKSAvZXRjL2hvc3RzIHwgL2Jpbi9hd2sgJ3twcmludCAkMX0nKSIgLUMgbHBvcnQ9JHBvcnQgfCBlY2hvICJwb3J0ICRwb3J0OiAkKC9iaW4vZ3JlcCAtUGkgJ15caCooYWxsb3d8ZGVueSkodXNlcnN8Z3JvdXBzKVxoK1xIKyhcaCsuKik/JCcpIjsgZG9uZSB8IC9iaW4vYXdrICdCRUdJTiB7Zj0wfSAvKGFsbG93fGRlbnkpKHVzZXJzfGdyb3VwcykvaSB7IGlmICgkTkYgfiAiOiIpIGYrKzsgcHJpbnQgJDB9IEVORCB7aWYgKE5SID09IDApIHByaW50ICJGYWlsOiBubyByZXN1bHRzIHJldHVybmVkIjsgZWxzZSBpZiAoZiA+IDApIHByaW50ICJGYWlsIjsgZWxzZSBwcmludCAiUGFzcyJ9JwogIH0=\" | openssl base64 -d -A | /bin/bash|cat"| Response : "/etc/ssh/sshd_config: Permission denied\nport 22: \nFail"| Error : ""| - Command : "LANG=C; echo \"IyEvYmluL2Jhc2gKICB7CiAgcG9ydHM9JCgvYmluL2dyZXAgLXMgLVAgIl4oUG9ydHxNYXRjaCkiIC9ldGMvc3NoL3NzaGRfY29uZmlnIC9ldGMvc3NoL3NzaGRfY29uZmlnLmQvKi5jb25mIHwgL2Jpbi9ncmVwIC1QIC1vICIoUG9ydHxMb2NhbFBvcnQpW1xzXStbXGRdKyIgfCAvYmluL2F3ayAne3ByaW50ICQyfTsgRU5EIHtpZiAoTlIgPT0gMCkgcHJpbnQgIjIyIn0nIHwgL2Jpbi91bmlxKTsgZm9yIHBvcnQgaW4gJHtwb3J0c1tAXX07IGRvIC9zYmluL3NzaGQgLVQgLUMgdXNlcj1yb290IC1DIGhvc3Q9IiQoaG9zdG5hbWUpIiAtQyBhZGRyPSIkKC9iaW4vZ3JlcCAkKGhvc3RuYW1lKSAvZXRjL2hvc3RzIHwgL2Jpbi9hd2sgJ3twcmludCAkMX0nKSIgLUMgbHBvcnQ9JHBvcnQgfCBlY2hvICJwb3J0ICRwb3J0OiAkKC9iaW4vZ3JlcCAtaSBeYmFubmVyKSI7IGRvbmUgfCAvYmluL2F3ayAnQkVHSU4ge2Y9MH0gL2Jhbm5lci9pIHsgaWYgKCRORiAhPSAiL2V0Yy9pc3N1ZS5uZXQiKSBmKys7IHByaW50ICQwfSBFTkQge2lmIChOUiA9PSAwKSBwcmludCAiRmFpbDogbm8gcmVzdWx0cyByZXR1cm5lZCI7IGVsc2UgaWYgKGYgPiAwKSBwcmludCAiRmFpbCI7IGVsc2UgcHJpbnQgIlBhc3MiIH0nCiAgfQ==\" | openssl base64 -d -A | /bin/bash|cat"| Response : "/etc/ssh/sshd_config: Permission denied\nport 22: \nFail"| Error : ""| - Command : "LANG=C; echo \"IyEvYmluL2Jhc2gKICB7CiAgcG9ydHM9JCgvYmluL2dyZXAgLXMgLVAgIl4oUG9ydHxNYXRjaCkiIC9ldGMvc3NoL3NzaGRfY29uZmlnIC9ldGMvc3NoL3NzaGRfY29uZmlnLmQvKi5jb25mIHwgL2Jpbi9ncmVwIC1QIC1vICIoUG9ydHxMb2NhbFBvcnQpW1xzXStbXGRdKyIgfCAvYmluL2F3ayAne3ByaW50ICQyfTsgRU5EIHtpZiAoTlIgPT0gMCkgcHJpbnQgIjIyIn0nIHwgL2Jpbi91bmlxKTsgZm9yIHBvcnQgaW4gJHtwb3J0c1tAXX07IGRvIC9zYmluL3NzaGQgLVQgLUMgdXNlcj1yb290IC1DIGhvc3Q9IiQoaG9zdG5hbWUpIiAtQyBhZGRyPSIkKC9iaW4vZ3JlcCAkKGhvc3RuYW1lKSAvZXRjL2hvc3RzIHwgL2Jpbi9hd2sgJ3twcmludCAkMX0nKSIgLUMgbHBvcnQ9JHBvcnQgfCBlY2hvICJwb3J0ICRwb3J0OiAkKC9iaW4vZ3JlcCAtaSBeY2lwaGVycykiOyBkb25lIHwgL2Jpbi9hd2sgJ0JFR0lOIHtmPTB9IC9jaXBoZXJzL2kgeyBpZiAoJE5GIH4gIigzZGVzfGJsb3dmaXNofGNhc3QxMjh8YWVzKDEyOHwxOTJ8MjU2KSktY2JjfGFyY2ZvdXIoMTI4fDI1Nik/fHJpam5kYWVsLWNiY0BseXNhdG9yXC5saXVcLnNlKSIpIGYrKzsgcHJpbnQgJDB9IEVORCB7aWYgKE5SID09IDApIHByaW50ICJGYWlsOiBubyByZXN1bHRzIHJldHVybmVkIjsgZWxzZSBpZiAoZiA+IDApIHByaW50ICJGYWlsIjsgZWxzZSBwcmludCAiUGFzcyIgfScKICB9\" | openssl base64 -d -A | /bin/bash|cat"| Response : "awk: cmd. line:1: warning: escape sequence `\\.' treated as plain `.'\n/etc/ssh/sshd_config: Permission denied\nport 22: \nPass"| Error : ""| - Command : "LANG=C; echo \"IyEvYmluL2Jhc2gKICB7CiAgcG9ydHM9JCgvYmluL2dyZXAgLXMgLVAgIl4oUG9ydHxNYXRjaCkiIC9ldGMvc3NoL3NzaGRfY29uZmlnIC9ldGMvc3NoL3NzaGRfY29uZmlnLmQvKi5jb25mIHwgL2Jpbi9ncmVwIC1QIC1vICIoUG9ydHxMb2NhbFBvcnQpW1xzXStbXGRdKyIgfCAvYmluL2F3ayAne3ByaW50ICQyfTsgRU5EIHtpZiAoTlIgPT0gMCkgcHJpbnQgIjIyIn0nIHwgL2Jpbi91bmlxKTsgZm9yIHBvcnQgaW4gJHtwb3J0c1tAXX07IGRvIC9zYmluL3NzaGQgLVQgLUMgdXNlcj1yb290IC1DIGhvc3Q9IiQoaG9zdG5hbWUpIiAtQyBhZGRyPSIkKC9iaW4vZ3JlcCAkKGhvc3RuYW1lKSAvZXRjL2hvc3RzIHwgL2Jpbi9hd2sgJ3twcmludCAkMX0nKSIgLUMgbHBvcnQ9JHBvcnQgfCBlY2hvICJwb3J0ICRwb3J0OiAkKC9iaW4vZ3JlcCAtaSBeY2xpZW50YWxpdmVjb3VudG1heCkiOyBkb25lIHwgL2Jpbi9hd2sgJ0JFR0lOIHtmPTB9IC9jbGllbnRhbGl2ZWNvdW50bWF4L2kgeyBpZiAoJE5GICF+IC9eWzEtOV1bMC05XSokLykgZisrOyBwcmludCAkMH0gRU5EIHtpZiAoTlIgPT0gMCkgcHJpbnQgIkZhaWw6IG5vIHJlc3VsdHMgcmV0dXJuZWQiOyBlbHNlIGlmIChmID4gMCkgcHJpbnQgIkZhaWwiOyBlbHNlIHByaW50ICJQYXNzIiB9JwogIH0=\" | openssl base64 -d -A | /bin/bash|cat"| Response : "/etc/ssh/sshd_config: Permission denied\nport 22: \nFail"| Error : ""| - Command : "LANG=C; echo \"IyEvYmluL2Jhc2gKICB7CiAgcG9ydHM9JCgvYmluL2dyZXAgLXMgLVAgIl4oUG9ydHxNYXRjaCkiIC9ldGMvc3NoL3NzaGRfY29uZmlnIC9ldGMvc3NoL3NzaGRfY29uZmlnLmQvKi5jb25mIHwgL2Jpbi9ncmVwIC1QIC1vICIoUG9ydHxMb2NhbFBvcnQpW1xzXStbXGRdKyIgfCAvYmluL2F3ayAne3ByaW50ICQyfTsgRU5EIHtpZiAoTlIgPT0gMCkgcHJpbnQgIjIyIn0nIHwgL2Jpbi91bmlxKTsgZm9yIHBvcnQgaW4gJHtwb3J0c1tAXX07IGRvIC9zYmluL3NzaGQgLVQgLUMgdXNlcj1yb290IC1DIGhvc3Q9IiQoaG9zdG5hbWUpIiAtQyBhZGRyPSIkKC9iaW4vZ3JlcCAkKGhvc3RuYW1lKSAvZXRjL2hvc3RzIHwgL2Jpbi9hd2sgJ3twcmludCAkMX0nKSIgLUMgbHBvcnQ9JHBvcnQgfCBlY2hvICJwb3J0ICRwb3J0OiAkKC9iaW4vZ3JlcCAtaSBeY2xpZW50YWxpdmVpbnRlcnZhbCkiOyBkb25lIHwgL2Jpbi9hd2sgJ0JFR0lOIHtmPTB9IC9jbGllbnRhbGl2ZWludGVydmFsL2kgeyBpZiAoJE5GICF+IC9eWzEtOV1bMC05XSokLykgZisrOyBwcmludCAkMH0gRU5EIHtpZiAoTlIgPT0gMCkgcHJpbnQgIkZhaWw6IG5vIHJlc3VsdHMgcmV0dXJuZWQiOyBlbHNlIGlmIChmID4gMCkgcHJpbnQgIkZhaWwiOyBlbHNlIHByaW50ICJQYXNzIiB9JwogIH0=\" | openssl base64 -d -A | /bin/bash|cat"| Response : "/etc/ssh/sshd_config: Permission denied\nport 22: \nFail"| Error : ""| - Command : "LANG=C; /bin/grep -rPi '^\\h*Defaults\\h+([^#\\n\\r]+ )?use_pty( \\h*\\h+\\h*)*\\h*(#.*)?$' /etc/sudoers* | /bin/awk '{print} END {if (NR != 0) print \"pass\" ; else print \"fail\"}'|cat"| Response : "/bin/grep: /etc/sudoers: Permission denied\n/bin/grep: /etc/sudoers.d: Permission denied\n/bin/grep: /etc/sudoers.d.backup.20251111_125948: Permission denied\nfail"| Error : ""| - Command : "LANG=C; cat '/etc/sudoers'|cat"| Response : "cat: /etc/sudoers: Permission denied"| Error : ""| - Command : "LANG=C; cat '/etc/pam.d/system-auth'|cat"| Response : "cat: /etc/pam.d/system-auth: Permission denied"| Error : ""| - Command : "LANG=C; cat '/etc/pam.d/password-auth'|cat"| Response : "cat: /etc/pam.d/password-auth: Permission denied"| Error : ""| - Command : "LANG=C; cat '/etc/shadow'|cat"| Response : "cat: /etc/shadow: Permission denied"| Error : ""| - Command : "LANG=C; echo \"IyEvYmluL2Jhc2gKICB7CiAgIHdoaWxlIElGUz0gcmVhZCAtciBsX3VzZXI7IGRvCiAgICAgIGxfY2hhbmdlPSQoZGF0ZSAtZCAiJChjaGFnZSAtLWxpc3QgJGxfdXNlciB8IGdyZXAgJ15MYXN0IHBhc3N3b3JkIGNoYW5nZScgfCBjdXQgLWQ6IC1mMiB8IGdyZXAgLXYgJ25ldmVyJCcpIiArJXMpCiAgICAgIGlmIFtbICIkbF9jaGFuZ2UiIC1ndCAiJChkYXRlICslcykiIF1dOyB0aGVuCiAgICAgICAgIGVjaG8gIlVzZXI6IFwiJGxfdXNlclwiIGxhc3QgcGFzc3dvcmQgY2hhbmdlIHdhcyBcIiQoY2hhZ2UgLS1saXN0ICRsX3VzZXIgfCBncmVwICdeTGFzdCBwYXNzd29yZCBjaGFuZ2UnIHwgY3V0IC1kOiAtZjIpXCIiCiAgICAgIGZpCiAgIGRvbmUgPCA8KGF3ayAtRjogJy9eW146XHJdKzpbXiEqeFhccl0ve3ByaW50ICQxfScgL2V0Yy9zaGFkb3cpCn0gfCAvYmluL2F3ayAne3ByaW50fSBFTkQge2lmIChOUiA9PSAwKSBwcmludCAiUGFzcyJ9Jw==\" | openssl base64 -d -A | /bin/bash|cat"| Response : "awk: fatal: cannot open file `/etc/shadow' for reading (Permission denied)\nPass"| Error : ""| - Command : "LANG=C; echo \"IyEvYmluL2Jhc2gKCnsKICAgbF9vcDI9IiIgbF9vdXRwdXQyPSIiCiAgIGxfdWlkbWluPSIkKGF3ayAnL15ccypVSURfTUlOL3twcmludCAkMn0nIC9ldGMvbG9naW4uZGVmcykiCiAgIGZpbGVfdGVzdF9jaGsoKQogICB7CiAgICAgIGxfb3AyPSIiCiAgICAgIGlmIFsgJCgoICRsX21vZGUgJiAkcGVybV9tYXNrICkpIC1ndCAwIF07IHRoZW4KICAgICAgICAgbF9vcDI9IiRsX29wMgogIC0gTW9kZTogXCIkbF9tb2RlXCIgc2hvdWxkIGJlIFwiJG1heHBlcm1cIiBvciBtb3JlIHJlc3RyaWN0aXZlIgogICAgICBmaQogICAgICBpZiBbWyAhICIkbF91c2VyIiA9fiAkbF9hdXNlciBdXTsgdGhlbgogICAgICAgICBsX29wMj0iJGxfb3AyCiAgLSBPd25lZCBieTogXCIkbF91c2VyXCIgYW5kIHNob3VsZCBiZSBvd25lZCBieSBcIiR7bF9hdXNlci8vfC8gb3IgfVwiIgogICAgICBmaQogICAgICBpZiBbWyAhICIkbF9ncm91cCIgPX4gJGxfYWdyb3VwIF1dOyB0aGVuCiAgICAgICAgIGxfb3AyPSIkbF9vcDIKICAtIEdyb3VwIG93bmVkIGJ5OiBcIiRsX2dyb3VwXCIgYW5kIHNob3VsZCBiZSBncm91cCBvd25lZCBieSBcIiR7bF9hZ3JvdXAvL3wvIG9yIH1cIiIKICAgICAgZmkKICAgICAgWyAtbiAiJGxfb3AyIiBdICYmIGxfb3V0cHV0Mj0iJGxfb3V0cHV0MgogLSBGaWxlOiBcIiRsX2ZuYW1lXCIgaXM6JGxfb3AyCiIKICAgfQogICB1bnNldCBhX2ZpbGUgJiYgYV9maWxlPSgpICMgY2xlYXIgYW5kIGluaXRpYWxpemUgYXJyYXkKICAgIyBMb29wIHRvIGNyZWF0ZSBhcnJheSB3aXRoIHN0YXQgb2YgZmlsZXMgdGhhdCBjb3VsZCBwb3NzaWJseSBmYWlsIG9uZSBvZiB0aGUgYXVkaXRzCiAgIHdoaWxlIElGUz0gcmVhZCAtciAtZCAkJ1wwJyBsX2ZpbGU7IGRvCiAgICAgIFsgLWUgIiRsX2ZpbGUiIF0gJiYgYV9maWxlKz0oIiQoc3RhdCAtTGMgJyVuXiUjYV4lVV4ldV4lR14lZycgIiRsX2ZpbGUiKSIpCiAgIGRvbmUgPCA8KGZpbmQgLUwgL3Zhci9sb2cgLXR5cGUgZiBcKCAtcGVybSAvMDEzNyAtbyAhIC11c2VyIHJvb3QgLW8gISAtZ3JvdXAgcm9vdCBcKSAtcHJpbnQwKQogICB3aGlsZSBJRlM9Il4iIHJlYWQgLXIgbF9mbmFtZSBsX21vZGUgbF91c2VyIGxfdWlkIGxfZ3JvdXAgbF9naWQ7IGRvCiAgICAgIGxfYm5hbWU9IiQoYmFzZW5hbWUgIiRsX2ZuYW1lIikiCiAgICAgIGNhc2UgIiRsX2JuYW1lIiBpbgogICAgICAgICBsYXN0bG9nIHwgbGFzdGxvZy4qIHwgd3RtcCB8IHd0bXAuKiB8IHd0bXAtKiB8IGJ0bXAgfCBidG1wLiogfCBidG1wLSogfCBSRUFETUUpCiAgICAgICAgICAgIHBlcm1fbWFzaz0nMDExMycKICAgICAgICAgICAgbWF4cGVybT0iJCggcHJpbnRmICclbycgJCgoIDA3NzcgJiB+JHBlcm1fbWFzaykpICkiCiAgICAgICAgICAgIGxfYXVzZXI9InJvb3QiCiAgICAgICAgICAgIGxfYWdyb3VwPSIocm9vdHx1dG1wKSIKICAgICAgICAgICAgZmlsZV90ZXN0X2NoawogICAgICAgICAgICA7OwogICAgICAgICBzZWN1cmUgfCBhdXRoLmxvZyB8IHN5c2xvZyB8IG1lc3NhZ2VzKQogICAgICAgICAgICBwZXJtX21hc2s9JzAxMzcnCiAgICAgICAgICAgIG1heHBlcm09IiQoIHByaW50ZiAnJW8nICQoKCAwNzc3ICYgfiRwZXJtX21hc2spKSApIgogICAgICAgICAgICBsX2F1c2VyPSIocm9vdHxzeXNsb2cpIgogICAgICAgICAgICBsX2Fncm91cD0iKHJvb3R8YWRtKSIKICAgICAgICAgICAgZmlsZV90ZXN0X2NoawogICAgICAgICAgICA7OwogICAgICAgICBTU1NEIHwgc3NzZCkKICAgICAgICAgICAgcGVybV9tYXNrPScwMTE3JwogICAgICAgICAgICBtYXhwZXJtPSIkKCBwcmludGYgJyVvJyAkKCggMDc3NyAmIH4kcGVybV9tYXNrKSkgKSIKICAgICAgICAgICAgbF9hdXNlcj0iKHJvb3R8U1NTRCkiCiAgICAgICAgICAgIGxfYWdyb3VwPSIocm9vdHxTU1NEKSIKICAgICAgICAgICAgZmlsZV90ZXN0X2NoawogICAgICAgICAgICA7OwogICAgICAgICBnZG0gfCBnZG0zKQogICAgICAgICAgICBwZXJtX21hc2s9JzAxMTcnCiAgICAgICAgICAgIG1heHBlcm09IiQoIHByaW50ZiAnJW8nICQoKCAwNzc3ICYgfiRwZXJtX21hc2spKSApIgogICAgICAgICAgICBsX2F1c2VyPSJyb290IgogICAgICAgICAgICBsX2Fncm91cD0iKHJvb3R8Z2RtfGdkbTMpIgogICAgICAgICAgICBmaWxlX3Rlc3RfY2hrCiAgICAgICAgICAgIDs7CiAgICAgICAgICouam91cm5hbCB8ICouam91cm5hbH4pCiAgICAgICAgICAgIHBlcm1fbWFzaz0nMDEzNycKICAgICAgICAgICAgbWF4cGVybT0iJCggcHJpbnRmICclbycgJCgoIDA3NzcgJiB+JHBlcm1fbWFzaykpICkiCiAgICAgICAgICAgIGxfYXVzZXI9InJvb3QiCiAgICAgICAgICAgIGxfYWdyb3VwPSIocm9vdHxzeXN0ZW1kLWpvdXJuYWwpIgogICAgICAgICAgICBmaWxlX3Rlc3RfY2hrCiAgICAgICAgICAgIDs7CiAgICAgICAgICopCiAgICAgICAgICAgIHBlcm1fbWFzaz0nMDEzNycKICAgICAgICAgICAgbWF4cGVybT0iJCggcHJpbnRmICclbycgJCgoIDA3NzcgJiB+JHBlcm1fbWFzaykpICkiCiAgICAgICAgICAgIGxfYXVzZXI9Iihyb290fHN5c2xvZykiCiAgICAgICAgICAgIGxfYWdyb3VwPSIocm9vdHxhZG0pIgogICAgICAgICAgICBpZiBbICIkbF91aWQiIC1sdCAiJGxfdWlkbWluIiBdICYmIFsgLXogIiQoYXdrIC12IGdycD0iJGxfZ3JvdXAiIC1GOiAnJDE9PWdycCB7cHJpbnQgJDR9JyAvZXRjL2dyb3VwKSIgXTsgdGhlbgogICAgICAgICAgICAgICBpZiBbWyAhICIkbF91c2VyIiA9fiAkbF9hdXNlciBdXTsgdGhlbgogICAgICAgICAgICAgICAgICBsX2F1c2VyPSIocm9vdHxzeXNsb2d8JGxfdXNlcikiCiAgICAgICAgICAgICAgIGZpCiAgICAgICAgICAgICAgIGlmIFtbICEgIiRsX2dyb3VwIiA9fiAkbF9hZ3JvdXAgXV07IHRoZW4KICAgICAgICAgICAgICAgICAgbF90c3Q9IiIKICAgICAgICAgICAgICAgICAgd2hpbGUgbF9vdXQzPSIiIHJlYWQgLXIgbF9kdWlkOyBkbwogICAgICAgICAgICAgICAgICAgICBbICIkbF9kdWlkIiAtZ2UgIiRsX3VpZG1pbiIgXSAmJiBsX3RzdD1mYWlsZWQKICAgICAgICAgICAgICAgICAgZG9uZSA8PDwgIiQoYXdrIC1GOiAnJDQ9PSciJGxfZ2lkIicge3ByaW50ICQzfScgL2V0Yy9wYXNzd2QpIgogICAgICAgICAgICAgICAgICBbICIkbF90c3QiICE9ICJmYWlsZWQiIF0gJiYgbF9hZ3JvdXA9Iihyb290fGFkbXwkbF9ncm91cCkiCiAgICAgICAgICAgICAgIGZpCiAgICAgICAgICAgIGZpCiAgICAgICAgICAgIGZpbGVfdGVzdF9jaGsKICAgICAgICAgICAgOzsKICAgICAgZXNhYwogICBkb25lIDw8PCAiJChwcmludGYgJyVzCicgIiR7YV9maWxlW0BdfSIpIgogICB1bnNldCBhX2ZpbGUgIyBDbGVhciBhcnJheQogICAjIElmIGFsbCBmaWxlcyBwYXNzZWQsIHRoZW4gd2UgcGFzcwogICBpZiBbIC16ICIkbF9vdXRwdXQyIiBdOyB0aGVuCiAgICAgIGVjaG8gLWUgIgotIEF1ZGl0IFJlc3VsdHM6CiAqKiBQYXNzICoqCi0gQWxsIGZpbGVzIGluIFwiL3Zhci9sb2cvXCIgaGF2ZSBhcHByb3ByaWF0ZSBwZXJtaXNzaW9ucyBhbmQgb3duZXJzaGlwCiIKICAgZWxzZQogICAgICAjIHByaW50IHRoZSByZWFzb24gd2h5IHdlIGFyZSBmYWlsaW5nCiAgICAgIGVjaG8gLWUgIgotIEF1ZGl0IFJlc3VsdHM6CiAqKiBGYWlsICoqCiRsX291dHB1dDIiCiAgIGZpCn0=\" | openssl base64 -d -A | /bin/bash|cat"| Response : "find: '/var/log/audit.old.backup.3810': Permission denied\nfind: '/var/log/audit': Permission denied\n\n- Audit Results:\n ** Fail **\n\n - File: \"/var/log/dmesg\" is:\n - Mode: \"0644\" should be \"640\" or more restrictive"| Error : ""| - Command : "LANG=C; cat '/etc/cron.allow'|cat"| Response : "cat: /etc/cron.allow: Permission denied"| Error : ""| - Command : "LANG=C; cat '/etc/cron.d'|cat"| Response : "cat: /etc/cron.d: Permission denied"| Error : ""| - Command : "LANG=C; cat '/etc/cron.daily'|cat"| Response : "cat: /etc/cron.daily: Permission denied"| Error : ""| - Command : "LANG=C; cat '/etc/cron.deny'|cat"| Response : "cat: /etc/cron.deny: Permission denied"| Error : ""| - Command : "LANG=C; cat '/etc/cron.hourly'|cat"| Response : "cat: /etc/cron.hourly: Permission denied"| Error : ""| - Command : "LANG=C; cat '/etc/cron.monthly'|cat"| Response : "cat: /etc/cron.monthly: Permission denied"| Error : ""| - Command : "LANG=C; cat '/etc/cron.weekly'|cat"| Response : "cat: /etc/cron.weekly: Permission denied"| Error : ""| - Command : "LANG=C; cat '/etc/crontab'|cat"| Response : "cat: /etc/crontab: Permission denied"| Error : ""| - Command : "LANG=C; echo \"IyEvYmluL2Jhc2gKCnsKICAgbF9vdXRwdXQ9IiIgbF9vdXRwdXQyPSIiIGxfb3V0cHV0Mz0iIgogICBsX2JmPSIiIGxfZGY9IiIgbF9uZj0iIiBsX2hmPSIiCiAgIGxfdmFsaWRfc2hlbGxzPSJeKCQoIGF3ayAtRlwvICckTkYgIT0gIm5vbG9naW4iIHtwcmludH0nIC9ldGMvc2hlbGxzIHwgc2VkIC1ybiAnL15cLy97cywvLFxcXFwvLGc7cH0nIHwgcGFzdGUgLXMgLWQgJ3wnIC0gKSkkIgogICB1bnNldCBhX3VhcnIgJiYgYV91YXJyPSgpICMgQ2xlYXIgYW5kIGluaXRpYWxpemUgYXJyYXkKICAgd2hpbGUgcmVhZCAtciBsX2VwdSBsX2VwaDsgZG8gIyBQb3B1bGF0ZSBhcnJheSB3aXRoIHVzZXJzIGFuZCB1c2VyIGhvbWUgbG9jYXRpb24KICAgICAgW1sgLW4gIiRsX2VwdSIgJiYgLW4gIiRsX2VwaCIgXV0gJiYgYV91YXJyKz0oIiRsX2VwdSAkbF9lcGgiKQogICBkb25lIDw8PCAiJChhd2sgLXYgcGF0PSIkbF92YWxpZF9zaGVsbHMiIC1GOiAnJChORikgfiBwYXQgeyBwcmludCAkMSAiICIgJChORi0xKSB9JyAvZXRjL3Bhc3N3ZCkiCiAgIGxfYXNpemU9IiR7I2FfdWFycltAXX0iICMgSGVyZSBpZiB3ZSB3YW50IHRvIGxvb2sgYXQgbnVtYmVyIG9mIHVzZXJzIGJlZm9yZSBwcm9jZWVkaW5nCiAgIGxfbWF4c2l6ZT0iMTAwMCIgIyBNYXhpbXVuIG51bWJlciBvZiBsb2NhbCBpbnRl
A5: oracle_post.nessus | B5: 192.168.0.75 | C5: RB-NT-201.redbelt.com.br | D5: 19506 | E5: tcp | F5: 0 | G5: 0 | H5: Settings | I5: Nessus Scan Information | J5: N/A | K5: N/A | L5: N/A | M5: N/A | N5: N/A | O5: N/A | P5: N/A | Q5: N/A | R5: N/A | S5: N/A | T5: Information about this scan : ||Nessus version : 10.10.1|Nessus build : 20010|Plugin feed version : 202511110033|Scanner edition used : Nessus|Scanner OS : WINDOWS|Scanner distribution : win-x86-64|Scan type : Normal|Scan name : Teste - Oracle Linux|Scan policy used : Policy Compliance Auditing|Scanner IP : 192.168.0.23|Port scanner(s) : netstat |Port range : default|Ping RTT : 282.402 ms|Thorough tests : no|Experimental tests : no|Scan for Unpatched Vulnerabilities : no|Plugin debugging enabled : no|Paranoia level : 1|Report verbosity : 1|Safe checks : yes|Optimize the test : yes|Credentialed checks : yes as 'master' via ssh|Attempt Least Privilege : no|Patch management checks : None|Display superseded patches : yes (supersedence plugin did not launch)|CGI scanning : disabled|Web application tests : disabled|Max hosts : 30|Max checks : 4|Recv timeout : 5|Backports : None|Allow post-scan editing : Yes|Nessus Plugin Signature Checking : Enabled|Audit File Signature Checking : Disabled|Scan Start Date : 2025/11/11 13:10 E. South America Standard Time (UTC -03:00)|Scan duration : 494 sec|Scan for malware : no|
A6: oracle_post.nessus | B6: 192.168.0.75 | C6: RB-NT-201.redbelt.com.br | D6: 55472 | E6: tcp | F6: 0 | G6: 0 | H6: General | I6: Device Hostname | J6: N/A | K6: N/A | L6: N/A | M6: N/A | N6: N/A | O6: N/A | P6: N/A | Q6: N/A | R6: N/A | S6: N/A | T6: | Hostname : ol7-vm| ol7-vm (hostname command)
A7: oracle_post.nessus | B7: 192.168.0.75 | C7: RB-NT-201.redbelt.com.br | D7: 33276 | E7: tcp | F7: 0 | G7: 0 | H7: General | I7: Enumerate MAC Addresses via SSH | J7: N/A | K7: N/A | L7: N/A | M7: N/A | N7: N/A | O7: N/A | P7: N/A | Q7: N/A | R7: N/A | S7: N/A | T7: |The following MAC address exists on the remote host :|| - 00:0c:29:3c:8a:36 (interface ens33)|
A8: oracle_post.nessus | B8: 192.168.0.75 | C8: RB-NT-201.redbelt.com.br | D8: 25203 | E8: tcp | F8: 0 | G8: 0 | H8: General | I8: Enumerate IPv4 Interfaces via SSH | J8: N/A | K8: N/A | L8: N/A | M8: N/A | N8: N/A | O8: N/A | P8: N/A | Q8: N/A | R8: N/A | S8: N/A | T8: |The following IPv4 addresses are set on the remote host :|| - 127.0.0.1 (on interface lo)| - 192.168.0.75 (on interface ens33)|
A9: oracle_post.nessus | B9: 192.168.0.75 | C9: RB-NT-201.redbelt.com.br | D9: 25202 | E9: tcp | F9: 0 | G9: 0 | H9: General | I9: Enumerate IPv6 Interfaces via SSH | J9: N/A | K9: N/A | L9: N/A | M9: N/A | N9: N/A | O9: N/A | P9: N/A | Q9: N/A | R9: N/A | S9: N/A | T9: |The following IPv6 interfaces are set on the remote host :|| - ::1 (on interface lo)| - fe80::edd3:b2e3:b0e3:cb8b (on interface ens33)|
A10: oracle_post.nessus | B10: 192.168.0.75 | C10: RB-NT-201.redbelt.com.br | D10: 14272 | E10: tcp | F10: 22 | G10: 0 | H10: Port scanners | I10: Netstat Portscanner (SSH) | J10: N/A | K10: N/A | L10: N/A | M10: N/A | N10: N/A | O10: N/A | P10: N/A | Q10: N/A | R10: N/A | S10: N/A | T10: Port 22/tcp was found to be open
A11: oracle_post.nessus | B11: 192.168.0.75 | C11: RB-NT-201.redbelt.com.br | D11: 14272 | E11: udp | F11: 68 | G11: 0 | H11: Port scanners | I11: Netstat Portscanner (SSH) | J11: N/A | K11: N/A | L11: N/A | M11: N/A | N11: N/A | O11: N/A | P11: N/A | Q11: N/A | R11: N/A | S11: N/A | T11: Port 68/udp was found to be open

Sheet ScanInfo
A1: 'Home Worksheet'!A1
A2: File | B2: IP Address | C2: FQDN | D2: Operating System | E2: System Type | F2: Scan Start | G2: Scan End | H2: Scan Duration | I2: Experimental Tests | J2: Credentialed Checks | K2: Patch Management Checks | L2: Safe Checks | M2: CGI Scanning | N2: We Application Tests | O2: Paranoia level | P2: Thorough tests
A3: oracle_post.nessus | B3: 192.168.0.75 | C3: 192.168.0.75 | D3: Linux Kernel 4.14.35-2047.543.3.1.el7uek.x86_64 on Oracle Linux Server release 7.9 | E3: general-purpose | F3: Tue Nov 11 13:09:52 2025 | G3: Tue Nov 11 13:18:28 2025 | H3: 494 sec | I3: no | J3: yes as 'master' via ssh | K3: None | L3: yes | M3: disabled | N3: disabled | O3: 1 | P3: no

Sheet CVSSv3 Score Total
A1: 'Home Worksheet'!A1
B2: Critical | C2: High | D2: Medium
A3: Multiplier | B3: 1 | C3: 1 | D3: 1
A5: Host IP Address | B5: Total | C5: Base Total | D5: Temporal Total | E5: Base Critical Severity (4) | F5: Temporal Critical Severity (4) | G5: Base High Severity (3) | H5: Temporal High Severity (3) | I5: Base Medium Severity (2) | J5: Temporal Medium Severity (2)

Sheet Information
A1: 'Home Worksheet'!A1
A2: File | B2: plugin Family | C2: plugin id | D2: plugin Name | E2: count | F2: Bid | G2: CVE | H2: OSVDB | I2: CVSSv3 Vector | J2: CVSSv3 Base Score | K2: CVSSv3 Temporal Score | L2: Solution | M2: Description | N2: Exploitability Ease | O2: Exploit Available | P2: Exploit Framework Canvas | Q2: Exploit Framework Metasploit | R2: Exploit Framework Core | S2: Metasploit Name | T2: Canvas Package | U2: Solution | V2: Synopsis | W2: plugin_publication_date | X2: plugin_modification_date | Y2: patch_publication_date | Z2: vuln_publication_date
A3: oracle_post.nessus | B3: Settings | C3: 141118 | D3: Target Credential Status by Authentication Protocol - Valid Credentials Provided | E3: 1 | I3: N/A | J3: N/A | K3: N/A | L3: n/a | M3: Nessus was able to determine that valid credentials were provided for an authentication protocol available on the remote target because it was able to successfully authenticate directly to the remote target using that authentication protocol at least once. Authentication was successful because the authentication protocol service was available remotely| the service was able to be identified| the authentication protocol was able to be negotiated successfully| and a set of credentials provided in the scan policy for that authentication protocol was accepted by the remote service. See plugin output for details| including protocol| port| and account. Please note the following : - This plugin reports per protocol| so it is possible for valid credentials to be provided for one protocol and not another. For example| authentication may succeed via SSH but fail via SMB| while no credentials were provided for an available SNMP service. - Providing valid credentials for all available authentication protocols may improve scan coverage| but the value of successful authentication for a given protocol may vary from target to target depending upon what data (if any) is gathered from the target via that protocol. For example| successful authentication via SSH is more valuable for Linux targets than for Windows targets| and likewise successful authentication via SMB is more valuable for Windows targets than for Linux targets. | N3: N/A | O3: N/A | P3: N/A | Q3: N/A | R3: N/A | S3: N/A | T3: N/A | U3: n/a | V3: Valid credentials were provided for an available authentication protocol. | W3: 2020/10/15 | X3: 2024/03/25
A4: oracle_post.nessus | B4: Settings | C4: 102094 | D4: SSH Commands Require Privilege Escalation | E4: 1 | H4: IAVB:0001-B-0507 | I4: N/A | J4: N/A | K4: N/A | L4: n/a | M4: This plugin reports the SSH commands that failed with a response indicating that privilege escalation is required to run them. Either privilege escalation credentials were not provided| or the command failed to run with the provided privilege escalation credentials. NOTE: Due to limitations inherent to the majority of SSH servers| this plugin may falsely report failures for commands containing error output expected by sudo| such as 'incorrect password'| 'not in the sudoers file'| or 'not allowed to execute'. | N4: N/A | O4: N/A | P4: N/A | Q4: N/A | R4: N/A | S4: N/A | T4: N/A | U4: n/a | V4: This plugin reports the SSH commands that failed with a response indicating that privilege escalation is required to run them. | W4: 2017/08/01 | X4: 2020/09/22
A5: oracle_post.nessus | B5: Settings | C5: 19506 | D5: Nessus Scan Information | E5: 1 | I5: N/A | J5: N/A | K5: N/A | L5: n/a | M5: This plugin displays| for each tested host| information about the scan itself : - The version of the plugin set. - The type of scanner (Nessus or Nessus Home). - The version of the Nessus Engine. - The port scanner(s) used. - The port range scanned. - The ping round trip time - Whether credentialed or third-party patch management checks are possible. - Whether the display of superseded patches is enabled - The date of the scan. - The duration of the scan. - The number of hosts scanned in parallel. - The number of checks done in parallel. | N5: N/A | O5: N/A | P5: N/A | Q5: N/A | R5: N/A | S5: N/A | T5: N/A | U5: n/a | V5: This plugin displays information about the Nessus scan. | W5: 2005/08/26 | X5: 2025/10/29
A6: oracle_post.nessus | B6: General | C6: 55472 | D6: Device Hostname | E6: 1 | I6: N/A | J6: N/A | K6: N/A | L6: n/a | M6: This plugin reports a device's hostname collected via SSH or WMI. | N6: N/A | O6: N/A | P6: N/A | Q6: N/A | R6: N/A | S6: N/A | T6: N/A | U6: n/a | V6: It was possible to determine the remote system hostname. | W6: 2011/06/30 | X6: 2025/11/03
A7: oracle_post.nessus | B7: General | C7: 33276 | D7: Enumerate MAC Addresses via SSH | E7: 1 | I7: N/A | J7: N/A | K7: N/A | L7: Disable any unused interfaces. | M7: Nessus was able to enumerate MAC addresses by connecting to the remote host via SSH with the supplied credentials. | N7: N/A | O7: N/A | P7: N/A | Q7: N/A | R7: N/A | S7: N/A | T7: N/A | U7: Disable any unused interfaces. | V7: Nessus was able to enumerate MAC addresses on the remote host. | W7: 2008/06/30 | X7: 2022/12/20
A8: oracle_post.nessus | B8: General | C8: 25203 | D8: Enumerate IPv4 Interfaces via SSH | E8: 1 | I8: N/A | J8: N/A | K8: N/A | L8: Disable any unused IPv4 interfaces. | M8: Nessus was able to enumerate the network interfaces configured with IPv4 addresses by connecting to the remote host via SSH using the supplied credentials. | N8: N/A | O8: N/A | P8: N/A | Q8: N/A | R8: N/A | S8: N/A | T8: N/A | U8: Disable any unused IPv4 interfaces. | V8: Nessus was able to enumerate the IPv4 interfaces on the remote host. | W8: 2007/05/11 | X8: 2025/09/24
A9: oracle_post.nessus | B9: General | C9: 25202 | D9: Enumerate IPv6 Interfaces via SSH | E9: 1 | I9: N/A | J9: N/A | K9: N/A | L9: Disable IPv6 if you are not actually using it. Otherwise| disable any unused IPv6 interfaces. | M9: Nessus was able to enumerate the network interfaces configured with IPv6 addresses by connecting to the remote host via SSH using the supplied credentials. | N9: N/A | O9: N/A | P9: N/A | Q9: N/A | R9: N/A | S9: N/A | T9: N/A | U9: Disable IPv6 if you are not actually using it. Otherwise| disable any unused IPv6 interfaces. | V9: Nessus was able to enumerate the IPv6 interfaces on the remote host. | W9: 2007/05/11 | X9: 2025/09/24

Sheet CPE Report Data
A1: 'Home Worksheet'!A1
A2: File | B2: IP Address | C2: FQDN | D2: Netbios Name | E2: Name | F2: Plugin Family | G2: Plugin ID | H2: Plugin Name | I2: CPE | J2: CPE Source

Sheet Device Type
A1: 'Home Worksheet'!A1
A2: File | B2: IP Address | C2: FQDN | D2: Netbios Name | E2: Name | F2: Device Type | G2: Confidence Level

Sheet HostConfigData
A1: 'Home Worksheet'!A1
A2: File | B2: IP Address | C2: FQDN | D2: Netbios Name | E2: OS | F2: Local Check Protocol | G2: MAC Address | H2: IP / Name | I2: Severity None (0) | J2: Severity Low (1) | K2: Severity Medium (2) | L2: Severity High (3) | M2: Severity Critical (4) | N2: Minimum password len | O2: Password history len | P2: Maximum password age days | Q2: Password must meet complexity requirements | R2: Minimum password age days | S2: Forced logoff time Seconds | T2: Locked account time seconds | U2: Time between failed logon seconds | V2: Number of invalid logon before locked out seconds
A3: oracle_post.nessus | B3: 192.168.0.75 | C3: RB-NT-201.redbelt.com.br | E3: Linux Kernel 4.14.35-2047.543.3.1.el7uek.x86_64 on Oracle Linux Server release 7.9 | F3: ssh | G3: 00:0C:29:3C:8A:36 4C:5F:70:AB:64:A4 | H3: 192.168.0.75 | I3: 10 | J3: 0 | K3: 0 | L3: 0 | M3: 0

Sheet portScanData
A1: 'Home Worksheet'!A1
A2: File | B2: IP Address | C2: FQDN | D2: Netbios Name | E2: OS | F2: Plugin Name | G2: Protocol | H2: Port | I2: Sevice Name | J2: Plugin Output | K2: DELETE
A3: oracle_post.nessus | B3: 192.168.0.75 | C3: RB-NT-201.redbelt.com.br | E3: Linux Kernel 4.14.35-2047.543.3.1.el7uek.x86_64 on Oracle Linux Server release 7.9 | F3: Netstat Portscanner (SSH) | G3: tcp | H3: 22 | I3: ssh | J3: Port 22/tcp was found to be open | K3: Port scanners
A4: oracle_post.nessus | B4: 192.168.0.75 | C4: RB-NT-201.redbelt.com.br | E4: Linux Kernel 4.14.35-2047.543.3.1.el7uek.x86_64 on Oracle Linux Server release 7.9 | F4: Netstat Portscanner (SSH) | G4: udp | H4: 68 | I4: bootpc? | J4: Port 68/udp was found to be open | K4: Port scanners

Sheet Sheet1
A3: Row Labels | B3: Count of Result
A4: ERROR | B4: 5
A5: FAILED | B5: 92
A6: PASSED | B6: 196
A7: WARNING | B7: 10
A8: Grand Total | B8: 303

Sheet Unix Policy
A1: File | B1: IP Address | C1: FQDN | D1: PluginID | E1: Severity | F1: Audit File | G1: Policy Setting | H1: Result | I1: System Value/Error Messages | J1: Compliance Requirement | K1: Description of Requirement | L1: Solution | M1: Authority Document | N1: Cross References
A2: oracle_post.nessus | B2: 192.168.0.75 | C2: RB-NT-201.redbelt.com.br | D2: 21157 | E2: 0 | F2: CIS_Oracle_Linux_7_v4.0.0_L1_Server.audit | G2: 1.1.1.1 Ensure cramfs kernel module is not available | H2: PASSED | I2: The command script with multiple lines returned : -- INFO -- - module: "cramfs" exists in: - "/lib/modules/3.10.0-1062.el7.x86_64/kernel/fs" - "/lib/modules/3.10.0-1160.119.1.0.5.el7.x86_64/kernel/fs" - "/lib/modules/4.14.35-1902.3.2.el7uek.x86_64/kernel/fs" - "/lib/modules/4.14.35-2047.543.3.1.el7uek.x86_64/kernel/fs" - Audit Result: ** PASS ** - module: "cramfs" is deny listed in: "/etc/modprobe.d/cramfs.conf" - module: "cramfs" is not loadable: "install /bin/false " - module: "cramfs" is not loaded | J2: cmd: multiple line script dont_echo_cmd: NO expect: (?i)^[\s]*\**[\s]*pass:?[\s]*\**$ | K2: The cramfs filesystem type is a compressed read-only Linux filesystem embedded in small footprint systems. A cramfs image can be used without having to first decompress the image. Removing support for unneeded filesystem types reduces the local attack surface of the system. If this filesystem type is not needed, disable it. | L2: Run the following script to disable the cramfs module: -IF- the module is available in the running kernel: - Create a file ending inconf with install cramfs /bin/false in the /etc/modprobe.d/ directory - Create a file ending inconf with blacklist cramfs in the /etc/modprobe.d/ directory - Unload cramfs from the kernel -IF- available in ANY installed kernel: - Create a file ending inconf with blacklist cramfs in the /etc/modprobe.d/ directory -IF- the kernel module is not available on the system or pre-compiled into the kernel: - No remediation is necessary #!/usr/bin/env bash { l_mname="cramfs" # set module name l_mtype="fs" # set module type l_mpath="/lib/modules/**/kernel/$l_mtype" l_mpname="$(tr '-' '_' <<< "$l_mname")" l_mndir="$(tr '-' '/' <<< "$l_mname")" module_loadable_fix() { # If the module is currently loadable, add "install {MODULE_NAME} /bin/false" to a file in "/etc/modprobe.d" l_loadable="$(modprobe -n -v "$l_mname")" [ "$(wc -l <<< "$l_loadable")" -gt "1" ] && l_loadable="$(grep -P -- "(^h*install|b$l_mname)b" <<< "$l_loadable")" if ! grep -Pq -- '^h*install /bin/(true|false)' <<< "$l_loadable"; then echo -e " - setting module: \"$l_mname\" to be not loadable" echo -e "install $l_mname /bin/false" >> /etc/modprobe.d/"$l_mpname".conf fi } module_loaded_fix() { # If the module is currently loaded, unload the module if lsmod | grep "$l_mname" > /dev/null 2>&1; then echo -e " - unloading module \"$l_mname\"" modprobe -r "$l_mname" fi } module_deny_fix() { # If the module isn't deny listed, denylist the module if ! modprobe --showconfig | grep -Pq -- "^h*blacklisth+$l_mpnameb"; then echo -e " - deny listing \"$l_mname\"" echo -e "blacklist $l_mname" >> /etc/modprobe.d/"$l_mpname".conf fi } # Check if the module exists on the system for l_mdir in $l_mpath; do if [ -d "$l_mdir/$l_mndir" ] && [ -n "$(ls -A $l_mdir/$l_mndir)" ]; then echo -e " - module: \"$l_mname\" exists in \"$l_mdir\" - checking if disabled..." module_deny_fix if [ "$l_mdir" = "/lib/modules/$(uname -r)/kernel/$l_mtype" ]; then module_loadable_fix module_loaded_fix fi else echo -e " - module: \"$l_mname\" doesn't exist in \"$l_mdir\" " fi done echo -e " - remediation of module: \"$l_mname\" complete " } | M2: https://workbench.cisecurity.org/benchmarks/15965 | N2: 800-171|3.4.2, 800-171|3.4.6, 800-171|3.4.7, 800-171r3|03.04.02, 800-171r3|03.04.06, 800-53|CM-6, 800-53|CM-7, 800-53r5|CM-6, 800-53r5|CM-7, CSCv7|9.2, CSCv8|4.8, CSF|PR.IP-1, CSF|PR.PT-3, CSF2.0|DE.CM-09, CSF2.0|PR.PS-01, GDPR|32.1.b, HIPAA|164.306(a)(1), ISO-27001-2022|A.8.9, ITSG-33|CM-6, ITSG-33|CM-7, LEVEL|1A, NIAv2|SS15a, PCI-DSSv3.2.1|2.2.2, SWIFT-CSCv1|2.3
A3: oracle_post.nessus | B3: 192.168.0.75 | C3: RB-NT-201.redbelt.com.br | D3: 21157 | E3: 0 | F3: CIS_Oracle_Linux_7_v4.0.0_L1_Server.audit | G3: 1.1.1.2 Ensure freevxfs kernel module is not available | H3: PASSED | I3: The command script with multiple lines returned : - Audit Result: ** PASS ** - module: "freevxfs" doesn't exist in "/lib/modules/3.10.0-1062.el7.x86_64/kernel/fs" - module: "freevxfs" doesn't exist in "/lib/modules/3.10.0-1160.119.1.0.5.el7.x86_64/kernel/fs" - module: "freevxfs" doesn't exist in "/lib/modules/4.14.35-1902.3.2.el7uek.x86_64/kernel/fs" - module: "freevxfs" doesn't exist in "/lib/modules/4.14.35-2047.543.3.1.el7uek.x86_64/kernel/fs" | J3: cmd: multiple line script dont_echo_cmd: NO expect: (?i)^[\s]*\**[\s]*pass:?[\s]*\**$ | K3: The freevxfs filesystem type is a free version of the Veritas type filesystem. This is the primary filesystem type for HP-UX operating systems. Removing support for unneeded filesystem types reduces the local attack surface of the system. If this filesystem type is not needed, disable it. | L3: Run the following script to disable the freevxfs module: -IF- the module is available in the running kernel: - Create a file ending inconf with install freevxfs /bin/false in the /etc/modprobe.d/ directory - Create a file ending inconf with blacklist freevxfs in the /etc/modprobe.d/ directory - Unload freevxfs from the kernel -IF- available in ANY installed kernel: - Create a file ending inconf with blacklist freevxfs in the /etc/modprobe.d/ directory -IF- the kernel module is not available on the system or pre-compiled into the kernel: - No remediation is necessary #!/usr/bin/env bash { l_mname="freevxfs" # set module name l_mtype="fs" # set module type l_mpath="/lib/modules/**/kernel/$l_mtype" l_mpname="$(tr '-' '_' <<< "$l_mname")" l_mndir="$(tr '-' '/' <<< "$l_mname")" module_loadable_fix() { # If the module is currently loadable, add "install {MODULE_NAME} /bin/false" to a file in "/etc/modprobe.d" l_loadable="$(modprobe -n -v "$l_mname")" [ "$(wc -l <<< "$l_loadable")" -gt "1" ] && l_loadable="$(grep -P -- "(^h*install|b$l_mname)b" <<< "$l_loadable")" if ! grep -Pq -- '^h*install /bin/(true|false)' <<< "$l_loadable"; then echo -e " - setting module: \"$l_mname\" to be not loadable" echo -e "install $l_mname /bin/false" >> /etc/modprobe.d/"$l_mpname".conf fi } module_loaded_fix() { # If the module is currently loaded, unload the module if lsmod | grep "$l_mname" > /dev/null 2>&1; then echo -e " - unloading module \"$l_mname\"" modprobe -r "$l_mname" fi } module_deny_fix() { # If the module isn't deny listed, denylist the module if ! modprobe --showconfig | grep -Pq -- "^h*blacklisth+$l_mpnameb"; then echo -e " - deny listing \"$l_mname\"" echo -e "blacklist $l_mname" >> /etc/modprobe.d/"$l_mpname".conf fi } # Check if the module exists on the system for l_mdir in $l_mpath; do if [ -d "$l_mdir/$l_mndir" ] && [ -n "$(ls -A $l_mdir/$l_mndir)" ]; then echo -e " - module: \"$l_mname\" exists in \"$l_mdir\" - checking if disabled..." module_deny_fix if [ "$l_mdir" = "/lib/modules/$(uname -r)/kernel/$l_mtype" ]; then module_loadable_fix module_loaded_fix fi else echo -e " - module: \"$l_mname\" doesn't exist in \"$l_mdir\" " fi done echo -e " - remediation of module: \"$l_mname\" complete " } | M3: https://workbench.cisecurity.org/benchmarks/15965 | N3: 800-171|3.4.2, 800-171|3.4.6, 800-171|3.4.7, 800-171r3|03.04.02, 800-171r3|03.04.06, 800-53|CM-6, 800-53|CM-7, 800-53r5|CM-6, 800-53r5|CM-7, CSCv7|9.2, CSCv8|4.8, CSF|PR.IP-1, CSF|PR.PT-3, CSF2.0|DE.CM-09, CSF2.0|PR.PS-01, GDPR|32.1.b, HIPAA|164.306(a)(1), ISO-27001-2022|A.8.9, ITSG-33|CM-6, ITSG-33|CM-7, LEVEL|1A, NIAv2|SS15a, PCI-DSSv3.2.1|2.2.2, SWIFT-CSCv1|2.3
A4: oracle_post.nessus | B4: 192.168.0.75 | C4: RB-NT-201.redbelt.com.br | D4: 21157 | E4: 0 | F4: CIS_Oracle_Linux_7_v4.0.0_L1_Server.audit | G4: 1.1.1.3 Ensure hfs kernel module is not available | H4: PASSED | I4: The command script with multiple lines returned : - Audit Result: ** PASS ** - module: "hfs" doesn't exist in "/lib/modules/3.10.0-1062.el7.x86_64/kernel/fs" - module: "hfs" doesn't exist in "/lib/modules/3.10.0-1160.119.1.0.5.el7.x86_64/kernel/fs" - module: "hfs" doesn't exist in "/lib/modules/4.14.35-1902.3.2.el7uek.x86_64/kernel/fs" - module: "hfs" doesn't exist in "/lib/modules/4.14.35-2047.543.3.1.el7uek.x86_64/kernel/fs" | J4: cmd: multiple line script dont_echo_cmd: NO expect: (?i)^[\s]*\**[\s]*pass:?[\s]*\**$ | K4: The hfs filesystem type is a hierarchical filesystem that allows you to mount Mac OS filesystems. Removing support for unneeded filesystem types reduces the local attack surface of the system. If this filesystem type is not needed, disable it. | L4: Run the following script to disable the hfs module: -IF- the module is available in the running kernel: - Create a file ending inconf with install hfs /bin/false in the /etc/modprobe.d/ directory - Create a file ending inconf with blacklist hfs in the /etc/modprobe.d/ directory - Unload hfs from the kernel -IF- available in ANY installed kernel: - Create a file ending inconf with blacklist hfs in the /etc/modprobe.d/ directory -IF- the kernel module is not available on the system or pre-compiled into the kernel: - No remediation is necessary #!/usr/bin/env bash { l_mname="hfs" # set module name l_mtype="fs" # set module type l_mpath="/lib/modules/**/kernel/$l_mtype" l_mpname="$(tr '-' '_' <<< "$l_mname")" l_mndir="$(tr '-' '/' <<< "$l_mname")" module_loadable_fix() { # If the module is currently loadable, add "install {MODULE_NAME} /bin/false" to a file in "/etc/modprobe.d" l_loadable="$(modprobe -n -v "$l_mname")" [ "$(wc -l <<< "$l_loadable")" -gt "1" ] && l_loadable="$(grep -P -- "(^h*install|b$l_mname)b" <<< "$l_loadable")" if ! grep -Pq -- '^h*install /bin/(true|false)' <<< "$l_loadable"; then echo -e " - setting module: \"$l_mname\" to be not loadable" echo -e "install $l_mname /bin/false" >> /etc/modprobe.d/"$l_mpname".conf fi } module_loaded_fix() { # If the module is currently loaded, unload the module if lsmod | grep "$l_mname" > /dev/null 2>&1; then echo -e " - unloading module \"$l_mname\"" modprobe -r "$l_mname" fi } module_deny_fix() { # If the module isn't deny listed, denylist the module if ! modprobe --showconfig | grep -Pq -- "^h*blacklisth+$l_mpnameb"; then echo -e " - deny listing \"$l_mname\"" echo -e "blacklist $l_mname" >> /etc/modprobe.d/"$l_mpname".conf fi } # Check if the module exists on the system for l_mdir in $l_mpath; do if [ -d "$l_mdir/$l_mndir" ] && [ -n "$(ls -A $l_mdir/$l_mndir)" ]; then echo -e " - module: \"$l_mname\" exists in \"$l_mdir\" - checking if disabled..." module_deny_fix if [ "$l_mdir" = "/lib/modules/$(uname -r)/kernel/$l_mtype" ]; then module_loadable_fix module_loaded_fix fi else echo -e " - module: \"$l_mname\" doesn't exist in \"$l_mdir\" " fi done echo -e " - remediation of module: \"$l_mname\" complete " } | M4: https://workbench.cisecurity.org/benchmarks/15965 | N4: 800-171|3.4.2, 800-171|3.4.6, 800-171|3.4.7, 800-171r3|03.04.02, 800-171r3|03.04.06, 800-53|CM-6, 800-53|CM-7, 800-53r5|CM-6, 800-53r5|CM-7, CSCv7|9.2, CSCv8|4.8, CSF|PR.IP-1, CSF|PR.PT-3, CSF2.0|DE.CM-09, CSF2.0|PR.PS-01, GDPR|32.1.b, HIPAA|164.306(a)(1), ISO-27001-2022|A.8.9, ITSG-33|CM-6, ITSG-33|CM-7, LEVEL|1A, NIAv2|SS15a, PCI-DSSv3.2.1|2.2.2, SWIFT-CSCv1|2.3
